Workbook
Name de: 'Dana Eks + PKS'!$E$5:$E$71
Name duplikasi: PI!$E$6:$E$231
Name index: Master!$F$10:$F$11
Name jdn: Master!$G$34:$G$35
Name jnjg: Master!$C$50:$C$53
Name jnski: Master!$A$10:$A$14
Name jnsolehan: Master!$C$34:$C$36
Name jnspi: Master!$A$17:$A$20
Name jnspwrp: Master!$C$25:$C$29
Name kelris: Master!$A$61:$A$68
Name ki: #REF!
Name mtr: Master!$J$25:$J$26
Name nmperiset: 'Rekap Capaian Individu'!$C$6:$C$119
Name outputdana: Master!$A$45:$A$47
Name periodestamp: Master!$A$70:$A$81
Name psv: Master!$E$50:$E$51
Name publikasi: PN!$E$6:$E$199
Name publikasi: PWRP!$E$6:$E$53
Name publikasi: PI!$E$6:$E$231
Name reppi: Master!$C$17:$C$20
Name reppn: Master!$F$17:$F$18
Name satuan: Master!$L$50:$L$52
Name smbrdana: Master!$A$34:$A$41
Name statki: Master!$A$2:$A$5
Name statpi: Master!$A$25:$A$30
Name statuskelris: Master!$C$70:$C$71
Name stspwrp: Master!$G$25:$G$31
Name stssdm: Master!$A$50:$A$55
Name stsupload: Master!$C$10:$C$11
Name vol: Master!$I$50:$I$52

Sheet PI
A1: PUBLIKASI INTERNASIONAL
A4: DIISI OLEH PJ MONEV | E4: PUSAT RISET SAINS DATA DAN INFORMASI | G4: PENULIS (SIVITAS PRSDI) | W4: JENIS DAKUNG
A5: NO | B5: Periode Input | C5: Periode Stamp | D5: Validasi KR | E5: JUDUL | F5: KELOMPOK RISET | G5: 1 | H5: 2 | I5: 3 | J5: 4 | K5: 5 | L5: 6 | M5: 7 | N5: 8 | O5: 9 | P5: 10 | Q5: NON SIVITAS PRSDI | R5: JENIS | S5: STATUS | T5: NAMA JURNAL/PROSIDING | U5: TERINDEX SCOPUS | V5: REPUTASI | W5: UPLOAD GDRIVE | X5: URL | Y5: DOI/SCOPUS (Wajib Jika status Published) | Z5: CATATAN
A6: 1 | B6: =IF(OR(E6<>"",F6<>""),IF(B6="",NOW(),B6),"") -> 45722.401 | E6: Analysis of alternatives methodology for large-scale information system implementation | F6: Temu Kembali Informasi (Information Retrieval) | G6: Andria Arisal, M. Eng. | Q6: Bambang Setiadi, Ichwanul Muslim | R6: Jurnal | S6: Published | T6: Bulletin of Electrical Engineering and Informatics | U6: Ya | V6: Q2 | W6: PI | X6: https://www.scopus.com/record/display.uri?eid=2-s2.0-85210507847&origin=resultslist | Y6: https://doi.org/10.11591/eei.v14i1.7800 | Z6: Sudah diklaim 2024 | AB6: Generate fuzzy string-matching to build self attention on Indonesian medical-chatbot | AC6: Published | AD6: https://doi.org/10.11591/ijece.v14i1.pp819-829 | AE6: PRSDI
A7: 2 | B7: =IF(OR(E7<>"",F7<>""),IF(B7="",NOW(),B7),"") -> 45722.401 | C7: Triwulan I | E7: Analysis of TRISO failure fraction in PeLUIt reactor with increasing power | F7: Rekayasa Pengetahuan dan Data (Knowledge and Data Engineering) | G7: Dr. Arya Adhyaksa Waskita, M.Si | Q7: Fitria Miftasani, Steven Wijaya, Nina Widiawati, Anni Nuril Hidayati, Dany Mulyana, Hakimul Wafda, Anik Purwaningsih, Fajar Al Afghani, Muhammad Ilham Bayquni, Topan Setiadipura | R7: Jurnal | S7: Published | T7: Nuclear Engineering and Design | U7: Ya | V7: Q2 | W7: PI | X7: https://www.scopus.com/record/display.uri?eid=2-s2.0-85214489294&origin=resultslist | Y7: https://doi.org/10.1016/j.nucengdes.2025.113842 | AB7: UAV-assisted heavy metal tracking in oil palm plantations: present applications and future prospects | AC7: Published | AD7: https://doi.org/10.1080/2150704X.2023.2299268
A8: 3 | B8: =IF(OR(E8<>"",F8<>""),IF(B8="",NOW(),B8),"") -> 45722.401 | C8: Triwulan I | E8: A Literature Review of Virtual Reality Exergames for Older Adults: Enhancing Physical, Cognitive, and Social Health | F8: Interaksi Manusia-Komputer dan Visualisasi (Human Computer Interaction and Visualisation) | G8: M. Yudhi Rezaldi, Ph.D | Q8: Xiacheng Song, Nazlena Mohamad Ali, Mohamad Hidir Mhd Salim | R8: Jurnal | S8: Published | T8: Applied Sciences (Switzerland) | U8: Ya | V8: Q2 | W8: PI | X8: https://www.scopus.com/record/display.uri?eid=2-s2.0-85214446910&origin=resultslist | Y8: https://doi.org/10.3390/app15010351 | AB8: Decision support system for fish quarantine measures in Indonesia | AC8: Published | AD8: https://doi.org/10.1108/VJIKMS-08-2021-0144
A9: 4 | B9: =IF(OR(E9<>"",F9<>""),IF(B9="",NOW(),B9),"") -> 45722.401 | C9: Triwulan I | E9: Clinical indicators for predicting physical activity levels in long-term COVID-19: Insights from physical exertion and oxygen saturation | F9: Pemerintahan Digital (Digital Government) | G9: Rezzy Eko Caraka ,S.Si.,M.Sc(RES).,PhD. | Q9: Triana Karnadipa, Aditya Denny Pratama, Riza Pahlawi, Mita Noviana, Chye Wah Yu, Yi Wan | R9: Jurnal | S9: Published | T9: Journal of Bodywork and Movement Therapies | U9: Ya | V9: Q2 | W9: PI | X9: https://www.scopus.com/record/display.uri?eid=2-s2.0-85212560912&origin=resultslist | Y9: https://doi.org/10.1016/j.jbmt.2024.11.031 | AB9: Investigating Adolescent Vulnerability in Indonesia: A Socio-Remote Sensing Big Data Analytics Study Using Night Light Data | AC9: Published | AD9: https://doi.org/10.1109/ACCESS.2024.3355963
A10: 5 | B10: =IF(OR(E10<>"",F10<>""),IF(B10="",NOW(),B10),"") -> 45722.401 | C10: Triwulan I | E10: Improved LSTM hyperparameters alongside sentiment walk-forward validation for time series prediction | F10: Pemerintahan Digital (Digital Government) | G10: Rezzy Eko Caraka ,S.Si.,M.Sc(RES).,PhD. | Q10: Eko Putra Wahyuddin, Wahyuddin E.P., Robert Kurniawan, Wahyu Caesarendra, Caesarendra W., Prana Ugiana Gio, Bens Pardamean | R10: Jurnal | S10: Published | T10: Journal of Open Innovation: Technology, Market, and Complexity | U10: Ya | V10: Q1 | W10: PI | X10: https://www.scopus.com/record/display.uri?eid=2-s2.0-85212942087&origin=resultslist | Y10: https://doi.org/10.1016/j.joitmc.2024.100458 | AB10: Implementing night light data as auxiliary variable of small area estimation | AC10: Published | AD10: https://doi.org/10.1080/03610926.2022.2077963
A11: 6 | B11: =IF(OR(E11<>"",F11<>""),IF(B11="",NOW(),B11),"") -> 45722.401 | C11: Triwulan I | E11: Bibliometric analysis of model vehicle routing problem in logistics delivery | F11: Pemerintahan Digital (Digital Government) | G11: Rezzy Eko Caraka ,S.Si.,M.Sc(RES).,PhD. | Q11: Muhammad Khahfi Zuhanda, Hartono, Samsul Abdul Rahman Sidik Hasibuan, Dahlan Abdullah, Prana Ugiana Gio | R11: Jurnal | S11: Published | T11: Indonesian Journal of Electrical Engineering and Computer Science | U11: Ya | V11: Q3 | W11: PI | X11: https://www.scopus.com/record/display.uri?eid=2-s2.0-85208030650&origin=resultslist | Y11: https://doi.org/10.11591/ijeecs.v37.i1.pp530-539 | AB11: Emphasizing Data Quality for the Identification of Chili Varieties in the Context of Smart Agriculture | AC11: Published | AD11: https://doi.org/10.28945/5257
A12: 7 | B12: =IF(OR(E12<>"",F12<>""),IF(B12="",NOW(),B12),"") -> 45722.401 | C12: Triwulan I | E12: The development of a Web-based in-text citation analysis tool | F12: Interaksi Manusia-Komputer dan Visualisasi (Human Computer Interaction and Visualisation) | G12: Dr. Ambar Yoganingrum | H12: Hayuning Titi Karsanti S. Kom., M.Eng | I12: Yaniasih | Q12: Ira Maryati, Gita Citra Puspita, Ekawati Marlina | R12: Jurnal | S12: Published | T12: Emerald Publisher | U12: Ya | V12: Q1 | W12: PI | X12: https://www.emerald.com/insight/content/doi/10.1108/lhtn-12-2024-0208/full/html | Y12: https://doi.org/10.1108/LHTN-12-2024-0208 | AB12: Improving Research Support Services in Indonesian Academic Digital Libraries: A Recommendation for Business Process Reengineering Implementation Strategies | AC12: Published | AD12: https://doi.org/10.5860/llm.v37i3.7559
A13: 8 | B13: =IF(OR(E13<>"",F13<>""),IF(B13="",NOW(),B13),"") -> 45722.401 | C13: Triwulan I | E13: The Digital Twin City in Enhancing Flood Evacuation Systems: Future Opportunities and Challenges | F13: Interaksi Manusia-Komputer dan Visualisasi (Human Computer Interaction and Visualisation) | G13: Dr. Ambar Yoganingrum | H13: Abdurrakhman Prasetyadi, M.P | I13: Prof. Dr. Ana Hadiana, M.Eng.Sc. | Q13: Ary Setijadi Prihatmanto, Ridwan Sutriadi | R13: Jurnal | S13: Published | T13: IEEE Access | U13: Ya | V13: Q1 | W13: PI | X13: https://ieeexplore.ieee.org/document/10876129 | Y13: https://doi.org/10.1109/ACCESS.2025.3539346 | AB13: The Evaluation of Fundamental Safety Function and Defence in Depth of AP1000 Using Probabilistic Analysis | AC13: Published | AD13: https://doi.org/10.1063/5.0192928
A14: 9 | B14: =IF(OR(E14<>"",F14<>""),IF(B14="",NOW(),B14),"") -> 45722.401 | C14: Triwulan I | E14: Bibliometrics for analysing business opportunities and players in the pharmaceuticals fields | F14: Interaksi Manusia-Komputer dan Visualisasi (Human Computer Interaction and Visualisation) | G14: Dr. Ambar Yoganingrum | H14: Dr. Eng. Budi Nugroho | I14: Siti Kania Kushadiani, S.T., M.Kom. | Q14: Yaniasih, Koharudin | R14: Jurnal | S14: Published | T14: International Journal of Technological Learning, Innovation and Development (IJTLID) | U14: Ya | V14: Q3 | W14: PI | X14: https://www.inderscienceonline.com/doi/abs/10.1504/IJTLID.2025.144531 | Y14: https://doi.org/10.1504/IJTLID.2025.144531 | AB14: Thematic evolution of smart learning environments, insights and directions from a 20-year research milestones: A bibliometric analysis | AC14: Published | AD14: https://doi.org/10.1016/j.heliyon.2024.e26191
A15: 10 | B15: =IF(OR(E15<>"",F15<>""),IF(B15="",NOW(),B15),"") -> 45722.419 | D15: ☑️ | E15: The development of a Web-based in-text citation analysis tool | F15: Rekayasa Pengetahuan dan Data (Knowledge and Data Engineering) | G15: Hayuning Titi Karsanti S. Kom., M.Eng | Q15: Ira Maryati, Yaniasih Yaniasih, Gita Citra Puspita, Ekawati Marlina | R15: Jurnal | S15: Published | T15: Emerald Publisher | U15: Ya | V15: Q1 | W15: PI | X15: https://www.emerald.com/insight/content/doi/10.1108/lhtn-12-2024-0208/full/html | Y15: https://doi.org/10.1108/LHTN-12-2024-0208 | AB15: Fine-Tuning of Predictive Models CNN-LSTM and CONV-LSTM for Nowcasting PM2.5Level | AC15: Published | AD15: https://doi.org/10.1109/ACCESS.2024.3368034
A16: 11 | B16: =IF(OR(E16<>"",F16<>""),IF(B16="",NOW(),B16),"") -> 45722.421 | D16: ☑️ | E16: Bibliometrics for analysing business opportunities and players in the pharmaceuticals fields | F16: Pemerintahan Digital (Digital Government) | G16: Dr. Eng. Budi Nugroho | Q16: Yaniasih, Koharudin | R16: Jurnal | S16: Published | T16: International Journal of Technological Learning, Innovation and Development (IJTLID) | U16: Ya | V16: Q3 | W16: PI | X16: https://www.inderscienceonline.com/doi/abs/10.1504/IJTLID.2025.144531 | Y16: https://doi.org/10.1504/IJTLID.2025.144531 | AB16: Business Predictive Analytics of Smallholder Indonesian Maize using Vector Error Correction | AC16: Published
A17: 12 | B17: =IF(OR(E17<>"",F17<>""),IF(B17="",NOW(),B17),"") -> 45729.497 | C17: Triwulan I | E17: Hyperparameter Tuning on Machine Learning-Based Landslide Susceptibility Mapping (Case study: Palu City and Its Surrounding areas) | F17: Temu Kembali Informasi (Information Retrieval) | G17: Andri Fachrur Rozie, M. Eng. | Q17: Sukristiyanti, Pamela, Moch Hilmi Zaenal Putra, Yukni Arifianti, Hilda Lestiana, Tri Muji Susantoro, Sumaryono, Yohandi Kristiawan, Iqbal Eras Putra | R17: Jurnal | S17: Published | T17: Indonesian Journal on Geoscience | U17: Ya | V17: Q3 | W17: PI | X17: https://www.scopus.com/record/display.uri?eid=2-s2.0-85219687867&origin=recordpage | Y17: https://doi.org/10.17014/ijog.12.1.43-53 | AB17: Empowering deaf communication: a novel LSTM model for recognizing Indonesian sign language | AC17: Published | AD17: https://doi.org/10.1007/s10209-024-01095-1
A18: 13 | B18: =IF(OR(E18<>"",F18<>""),IF(B18="",NOW(),B18),"") -> 45735.484 | E18: Remote Sensing Applications in Biodiversity Assessment and Conservation of the Sundaland Biodiversity Hotspot | F18: Rekayasa Pengetahuan dan Data (Knowledge and Data Engineering) | G18: Wawan Hendriawan Nur, S.Si., M.T. | H18: Aang Gunawan S, S.Kom., M.T. | I18: Dr. Eng. Budi Nugroho | Q18: Yuliana Susilowati, Waluyo Eko Cahyono, Ayubella Anggraini Leksono, Dewi Puspitasari Leksono, Putri Larasati Leksono, Redempta Bungan Krisetiawan Putri, Yugo Kumoro, Ibnu Maryanto | R18: Bag Buku | S18: Accepted | T18: Apple Academic Press | U18: Ya | W18: PI | AB18: Determinants of knowledge sharing among civil servants and the moderating effects of leadership styles | AC18: Published | AD18: https://doi.org/10.1177/02663821231216687
A19: 14 | B19: =IF(OR(E19<>"",F19<>""),IF(B19="",NOW(),B19),"") -> 45736.242 | C19: Triwulan I | E19: The Examining of 360∘ Media That Support Learning in Field of Education | F19: Interaksi Manusia-Komputer dan Visualisasi (Human Computer Interaction and Visualisation) | G19: M. Yudhi Rezaldi, Ph.D | Q19: Gema Ari Prahara | R19: Prosiding | S19: Published | T19: KnE Social Sciences | U19: Ya | W19: PI | X19: https://kneopen.com/KnE-Social/article/view/17900/ | Y19: https://doi.org/10.18502/kss.v10i3.17900 | AB19: The development land utilization and cover of the Jambi district are examined and forecasted using Google Earth Engine and CNN1D | AC19: Published | AD19: https://doi.org/10.1016/j.rsase.2024.101175
A20: 15 | B20: =IF(OR(E20<>"",F20<>""),IF(B20="",NOW(),B20),"") -> 45736.242 | E20: How could Virtual Reality Inclusively Improve Disaster Awareness to Tsunami? | F20: Interaksi Manusia-Komputer dan Visualisasi (Human Computer Interaction and Visualisation) | G20: M. Yudhi Rezaldi, Ph.D | Q20: Gusti Ayu Ketut Surtiari, Syarifah Aini Dalimunthe, Abdul Fikri Angga Reksa, Taro Arikawa and Diah Lenggogeni | R20: Prosiding | S20: Accepted | T20: AIWEST 2024 | U20: Ya | W20: PI | X20: https://eprints.uad.ac.id/80093/1/BOOK%20OF%20ABSTRACT-AIWEST%20DR%202024.pdf | AB20: Exploring usage-based and usability metrics for user experience for sus- tainable e-learning systems | AC20: Published | AD20: https://doi.org/10.1051/e3sconf/202450102003
A21: 16 | B21: =IF(OR(E21<>"",F21<>""),IF(B21="",NOW(),B21),"") -> 45737.621 | C21: Triwulan I | E21: Design and Construction of an Automatic Dispenser for the Visually Impaired Using Microcontroller Technology | F21: Interaksi Manusia-Komputer dan Visualisasi (Human Computer Interaction and Visualisation) | G21: Arafat Febriandirza, Ph.D | Q21: Abdiel Alpriyan Gempa Alamsyah Sahurib | R21: Prosiding | S21: Published | T21: ICMAT 2024 | U21: Ya | W21: PI | X21: https://www.scopus.com/record/display.uri?eid=2-s2.0-85215504172&origin=recordpage | Y21: https://doi.org/10.3233/ATDE241220 | Z21: Konferensi ICMAT pada akhir tahun 2024 belum diklaim dan indeks scopus muncul di tahun 2025 | AA21: https://ebooks.iospress.nl/doi/10.3233/ATDE241220 | AB21: Plant-Disease Relation Model through BERT-BiLSTM-CRF Approach | AC21: Published | AD21: https://doi.org/10.52549/ijeei.v12i1.5154
A22: 17 | B22: =IF(OR(E22<>"",F22<>""),IF(B22="",NOW(),B22),"") -> 45737.634 | C22: Triwulan I | E22: Smart Home Innovation: IOT-Based Lighting Control System Design | F22: Interaksi Manusia-Komputer dan Visualisasi (Human Computer Interaction and Visualisation) | G22: Christine Cecylia Munthe, S.Kom. | H22: Arafat Febriandirza, Ph.D | R22: Prosiding | S22: Published | T22: ICMAT 2024 | U22: Ya | W22: PI | X22: https://www.scopus.com/record/display.uri?eid=2-s2.0-85215511644&origin=recordpage | Y22: https://doi.org/10.3233/ATDE241310 | Z22: Konferensi ICMAT pada akhir tahun 2024 belum diklaim dan indeks scopus muncul di tahun 2025 | AA22: https://ebooks.iospress.nl/doi/10.3233/ATDE241310 | AB22: Unveiling Sentiments: Social Media Analytics on Indonesian Startup and Fintech Discourse | AC22: Published | AD22: https://doi.org/10.1109/ICETSIS61505.2024.10459378
A23: 18 | B23: =IF(OR(E23<>"",F23<>""),IF(B23="",NOW(),B23),"") -> 45741.49 | C23: April | E23: Exploring Features and Products in E-Commerce on Consumers Behavior using Cognitive Affective | F23: Pemerintahan Digital (Digital Government) | G23: Rezzy Eko Caraka ,S.Si.,M.Sc(RES).,PhD. | Q23: PAHRUDIN PAHRUDIN, LI-WEI LIU1, PRANA UGIANA GIO, NUR ANITA YUNIKAWATI, BENS PARDAMEAN | R23: Prosiding | S23: Published | T23: IEEE Access | U23: Ya | W23: PI | X23: https://ieeexplore.ieee.org/document/10934986 | Y23: https://doi.org/10.1109/ACCESS.2025.3553192 | AB23: Developing a Seismic Land Capability Framework for Earthquake-resistant Housing Based on GIS Approach: A Case of Sukabumi District | AC23: Published | AD23: https://doi.org/10.21163/GT_2024.191.12
A24: 19 | B24: =IF(OR(E24<>"",F24<>""),IF(B24="",NOW(),B24),"") -> 45764.773 | C24: Triwulan IV | E24: Comparative Performance Analysis of CNN-Architectures on Coffee-bean Roast Classification | F24: Temu Kembali Informasi (Information Retrieval) | G24: Irfan Asfy Fakhry Anto S.Kom., M.T | Q24: Jony Winaryo Wibowo, Taufik Ibnu Salim, Aris Munandar | R24: Jurnal | S24: Published | T24: Telecommunication Computing Electronics and Control | U24: Ya | V24: Q3 | W24: PI | X24: https://drive.google.com/file/d/1yjgKM3kYTg0HSk339-r_Yg230KeUajb-/view?usp=drive_link | Y24: https://doi.org/10.12928/TELKOMNIKA.v23i6.27090 | AB24: BERTopic Analysis of Indonesian Biodiversity Policy on Social Media | AC24: Published | AD24: https://doi.org/10.37936/ecti-cit.2024173.255058
A25: 20 | B25: =IF(OR(E25<>"",F25<>""),IF(B25="",NOW(),B25),"") -> 45768.35 | C25: April | E25: Leveraging YOLOv8 for Real-Time Parking Space Detection | F25: Interaksi Manusia-Komputer dan Visualisasi (Human Computer Interaction and Visualisation) | G25: Dr. Esa Prakasa, MT | H25: Dr. Eng. Ir Yuyun, S.Kom., M.T | Q25: Mahabintang Pallawabonang, Muh. Adnan, Sitti Zuhriyah, Amirul Mukmin | R25: Prosiding | S25: Published | T25: 2024 Beyond Technology Summit on Informatics International Conference (BTS-I2C) | U25: Ya | W25: PI | X25: https://ieeexplore.ieee.org/abstract/document/10942123 | Y25: https://doi.org/10.1109/BTS-I2C63534.2024.10942123 | AB25: A Systematic Literature Review on University Collaboration in Open Innovation: Trends, Technologies, and Frameworks | AC25: Published | AD25: https://doi.org/10.34190/ejkm.22.1.3407
A26: 21 | B26: =IF(OR(E26<>"",F26<>""),IF(B26="",NOW(),B26),"") -> 45768.35 | C26: April | E26: Leveraging the Pre-Trained Whisper Model and Levenshtein Distance for Audio Buginesse Transcription | F26: Pengolahan Bahasa Alami (Natural Language Processing) | G26: Dr. Eng. Ir Yuyun, S.Kom., M.T | H26: Dr. Esa Prakasa, MT | Q26: Amirul Mukmin, Muh. Adnan,Abdul Jalil, Mahabintang Pallawabonang | R26: Prosiding | S26: Published | T26: 2024 Beyond Technology Summit on Informatics International Conference (BTS-I2C) | U26: Ya | W26: PI | X26: https://ieeexplore.ieee.org/abstract/document/10942151 | Y26: https://doi.org/10.1109/BTS-I2C63534.2024.10942151 | AB26: Unraveling Knowledge-based Chatbot Adoption Intention in Enhancing Species Literacy | AC26: Published | AD26: https://doi.org/10.28945/5280
A27: 22 | B27: =IF(OR(E27<>"",F27<>""),IF(B27="",NOW(),B27),"") -> 45768.35 | C27: April | E27: Grammar Error Correction in Indonesian Sports News: Comparing the Performance of Pre-Trained T5 and BART Models | F27: Pengolahan Bahasa Alami (Natural Language Processing) | G27: Dr. Eng. Ir Yuyun, S.Kom., M.T | H27: Dr. Esa Prakasa, MT | Q27: Muh. Adnan, Najirah Umar, Nasrullah, Adi Sadli, A. Edeth Fuari Anatasya, Hazriani, Mashur Razak | R27: Prosiding | S27: Published | T27: 2024 Beyond Technology Summit on Informatics International Conference (BTS-I2C) | U27: Ya | W27: PI | X27: https://ieeexplore.ieee.org/abstract/document/10941994 | Y27: https://doi.org/10.1109/BTS-I2C63534.2024.10941994 | AB27: Transactional Business Process Redesign of Procurement Planning System using Heuristic Method | AC27: Published | AD27: https://doi.org/10.1109/ICoSEIT60086.2024.10497473
A28: 23 | B28: =IF(OR(E28<>"",F28<>""),IF(B28="",NOW(),B28),"") -> 45768.361 | D28: ☑️ | E28: Leveraging YOLOv8 for Real-Time Parking Space Detection | F28: Pengolahan Bahasa Alami (Natural Language Processing) | G28: Dr. Eng. Ir Yuyun, S.Kom., M.T | Q28: Mahabintang Pallawabonang, Muh. Adnan, Sitti Zuhriyah, Amirul Mukmin | R28: Prosiding | S28: Published | T28: 2024 Beyond Technology Summit on Informatics International Conference (BTS-I2C) | U28: Ya | W28: PI | X28: https://ieeexplore.ieee.org/abstract/document/10942123 | Y28: https://doi.org/10.1109/BTS-I2C63534.2024.10942123 | AB28: Supply chain pattern of blue swimming crabs in the north coast of Java, Indonesia | AC28: Published | AD28: https://doi.org/10.5267/j.uscm.2024.5.007
A29: 24 | B29: =IF(OR(E29<>"",F29<>""),IF(B29="",NOW(),B29),"") -> 45768.366 | D29: ☑️ | E29: Leveraging the Pre-Trained Whisper Model and Levenshtein Distance for Audio Buginesse Transcription | F29: Interaksi Manusia-Komputer dan Visualisasi (Human Computer Interaction and Visualisation) | G29: Dr. Esa Prakasa, MT | Q29: Amirul Mukmin, Muh. Adnan,Abdul Jalil, Mahabintang Pallawabonang | R29: Prosiding | S29: Published | T29: 2024 Beyond Technology Summit on Informatics International Conference (BTS-I2C) | U29: Ya | W29: PI | X29: https://ieeexplore.ieee.org/abstract/document/10942151 | Y29: https://doi.org/10.1109/BTS-I2C63534.2024.10942151 | AB29: Technology readiness level assessment of system information zoonosis and emerging infectious disease | AC29: Published | AD29: https://doi.org/10.1063/5.0208106
A30: 25 | B30: =IF(OR(E30<>"",F30<>""),IF(B30="",NOW(),B30),"") -> 45768.368 | D30: ☑️ | E30: Grammar Error Correction in Indonesian Sports News: Comparing the Performance of Pre-Trained T5 and BART Models | F30: Interaksi Manusia-Komputer dan Visualisasi (Human Computer Interaction and Visualisation) | G30: Dr. Esa Prakasa, MT | Q30: Muh. Adnan, Najirah Umar, Nasrullah, Adi Sadli, A. Edeth Fuari Anatasya, Hazriani, Mashur Razak | R30: Prosiding | S30: Published | T30: 2024 Beyond Technology Summit on Informatics International Conference (BTS-I2C) | U30: Ya | W30: PI | X30: https://ieeexplore.ieee.org/abstract/document/10941994 | Y30: https://doi.org/10.1109/BTS-I2C63534.2024.10941994 | AB30: Measurement of Si Pixel Sensor Alignment for the ALICE ITS Detector | AC30: Published | AD30: https://doi.org/10.1088/1361-6501/ad4fae
A31: 26 | B31: =IF(OR(E31<>"",F31<>""),IF(B31="",NOW(),B31),"") -> 45770.547 | C31: April | E31: Internet Service Assessment in Lombok Barat Regency | F31: Pemerintahan Digital (Digital Government) | G31: Dr. Eng. Budi Nugroho | H31: Dra. Andrari Grahitandaru, M.Sc. | Q31: Sumirah | R31: Prosiding | S31: Published | T31: INTERNATIONAL CONFERENCE ON INFORMATION TECHNOLOGY SYSTEMS AND INNOVATION (ICITSI 2024) | U31: Ya | W31: PI | X31: https://ieeexplore.ieee.org/abstract/document/10929191 | Y31: https://doi.org/10.1109/ICITSI65188.2024.10929191 | Z31: ICITSI 2024 dilaksanakan pada bulan Desember 2024, dan baru terbit di IEEE Xplore pada bulan Maret 2025. Paper belum kami klaim sebagai capaian di tahun 2024. | AB31: An Analysis of the Open Government Data Ecosystem in Tangerang Regency to Promote Data Sharing Initiatives | AC31: Published | AD31: https://doi.org/10.1109/IC3INA64086.2024.10732524
A32: 27 | B32: =IF(OR(E32<>"",F32<>""),IF(B32="",NOW(),B32),"") -> 45770.55 | C32: April | E32: On the Use of Remote Sensing Data for Monitoring NDVI Anomalies and Correlations with Rainfall Anomalies in West Java Province, Indonesia: Addressing Sustainable Development Goal 2 | F32: Pemerintahan Digital (Digital Government) | G32: Hengki Muradi, M.Si. | Q32: Orbita Roswintiarti, Novie Indriasari, Fadilah Halim Rasyidi, Inggit Lolita Sari, Kustiyo, Babag Purbantoro, Ansy Indrajad, Akhmad Ubehi | R32: Jurnal | S32: Published | T32: Remote Sensing in Earth Systems Sciences | U32: Ya | V32: Q2 | W32: PI | X32: https://link.springer.com/content/pdf/10.1007/s41976-025-00222-7.pdf | Y32: https://doi.org/10.1007/s41976-025-00222-7 | AB32: A qualitative exploration of challenges and factors in research data management across Indonesian research institutes | AC32: Published | AD32: https://doi.org/10.1177/09610006241252662
A33: 28 | B33: =IF(OR(E33<>"",F33<>""),IF(B33="",NOW(),B33),"") -> 45775.63 | C33: April | E33: Community preparedness for earthquake disasters: A preliminary assessment of awareness and disaster infrastructure response in Cianjur, West Java-Indonesia | F33: Pengolahan Bahasa Alami (Natural Language Processing) | G33: Prabu Kresna Putra, S.T., M.T.I. | Q33: Dewayany Sutrisno, Yatin Suwarno, Ati Rahadiati, Muhammad Iqbal Habibie, Hari Prayogi, Amien Widodo, Fathia Zulfati Sabrina, Ahmad Kosasih | R33: Jurnal | S33: Published | T33: F1000Research | U33: Ya | V33: Q2 | W33: PI | X33: https://www.scopus.com/record/display.uri?eid=2-s2.0-86000769038&origin=recordpage | Y33: https://doi.org/10.12688/f1000research.143577.3 | AB33: Air Quality Monitoring in Indonesia | AC33: Published | AD33: https://doi.org/10.1109/AGERS61027.2023.10490762
A34: 29 | B34: =IF(OR(E34<>"",F34<>""),IF(B34="",NOW(),B34),"") -> 45775.78 | C34: April | E34: The recognition and protection of customary law communities in maintaining culture as a tourist attraction in Sembalun village East Lombok | F34: Pemerintahan Digital (Digital Government) | G34: Rezzy Eko Caraka ,S.Si.,M.Sc(RES).,PhD. | Q34: Komang Mahawira, Ali Muhtasom, Amirosa Ria Satiadji, Achlan Fahlevi Royanow | R34: Jurnal | S34: Published | T34: International Journal of Innovative Research and Scientific Studies | U34: Ya | V34: Q2 | W34: PI | X34: https://www.scopus.com/record/display.uri?eid=2-s2.0-105000200852&origin=recordpage | Y34: https://doi.org/10.53894/ijirss.v8i2.5289 | AB34: Exploring Regional Dynamics Through Social Media Conversations and Socio-Economic Surveys: Uncovering Perspectives on the Cianjur Earthquake | AC34: Published | AD34: https://doi.org/10.1109/AGERS61027.2023.10490691
A35: 30 | B35: =IF(OR(E35<>"",F35<>""),IF(B35="",NOW(),B35),"") -> 45780.486 | C35: Mei | E35: Strategies to encourage data owners to self-archive data sets | F35: Interaksi Manusia-Komputer dan Visualisasi (Human Computer Interaction and Visualisation) | G35: Dr. Ambar Yoganingrum | Q35: Danarsiwi Tri Lastiwi, Ekawati Marlina, Seno Yudhanto, Dhian Kusumawardhani | R35: Jurnal | S35: Published | T35: Library Hi Tech News (LHTN) | U35: Ya | V35: Q1 | W35: PI | X35: https://www.emerald.com/insight/content/doi/10.1108/lhtn-03-2025-0044/full/html?skipTracking=true | Y35: https://doi.org/10.1108/LHTN-03-2025-0044 | AB35: The Role of Data Governance in a High-Level Approach of Data Migration to Open Data | AC35: Published | AD35: https://doi.org/10.1177/02663821241264702
A36: 31 | B36: =IF(OR(E36<>"",F36<>""),IF(B36="",NOW(),B36),"") -> 45780.487 | C36: Mei | E36: Chili leaf segmentation using meta-learning for improved model accuracy | F36: Temu Kembali Informasi (Information Retrieval) | G36: Dr. Wiwin Suwarningsih, M.T. | H36: Dr. Purnomo Husnul Khotimah, M.T | I36: Ir. Dianadewi Riswantini, M. Sc., M.B.A. | J36: Andri Fachrur Rozie, M. Eng. | K36: Ekasari Nugraheni, M.T. | L36: Andria Arisal, M. Eng. | M36: Devi Munandar, S.Kom., M.Mat. | Q36: Rinda Kirana, Noor Roufiq Ahmadi | R36: Jurnal | S36: Published | T36: Bulletin of Electrical Engineering and Informatics (BEEI) | U36: Ya | V36: Q3 | W36: PI | X36: https://beei.org/index.php/EEI/article/view/7929/4237 | Y36: https://doi.org/10.11591/eei.v14i3.7929 | AB36: A Grouper Fish Mortality Prediction Model Using Transfer Learning Approach | AC36: Published | AD36: https://doi.org/10.1109/AIMS61812.2024.10513177
A37: 32 | B37: =IF(OR(E37<>"",F37<>""),IF(B37="",NOW(),B37),"") -> 45832.683 | C37: Triwulan II | E37: Virtual reality as a pandemic solution: adapting education, working, tourism, and industrial in COVID-19 situation | F37: Interaksi Manusia-Komputer dan Visualisasi (Human Computer Interaction and Visualisation) | G37: M. Yudhi Rezaldi, Ph.D | H37: Dr. Ambar Yoganingrum | I37: Dr. Esa Prakasa, MT | J37: Arafat Febriandirza, Ph.D | K37: Rio Nurtantyana, S.Pd., M.Pd., M.Sc., Ph.D. | L37: Abdurrakhman Prasetyadi, M.P | M37: Aria Bisri, S.Kom. M.T. | N37: Ridwan Suhud, S.Kom., M.T. | O37: Christine Cecylia Munthe, S.Kom. | P37: Rumadi, S.T., M.T. | Q37: Nazlena Mohamad Ali, Cahyo Trianggoro | R37: Bag Buku | S37: Published | T37: The Prediction of Future Pandemic (Elsevier) | U37: Ya | W37: PI | X37: https://www.sciencedirect.com/science/article/abs/pii/B9780443338717000179 | Y37: https://doi.org/10.1016/B978-0-443-33871-7.00017-9 | AB37: Requirements Engineering of Knowledge Management System for Smallholder Dairy Farmers | AC37: Published | AD37: https://doi.org/10.28991/HEF-2024-05-02-02
A38: 33 | B38: =IF(OR(E38<>"",F38<>""),IF(B38="",NOW(),B38),"") -> 45800.193 | C38: Mei | E38: Automated Detection of Helmet Wearing with YOLOv8 and Real-Time Monitoring for Factory Safety | F38: Temu Kembali Informasi (Information Retrieval) | G38: Dr. Wiwin Suwarningsih, M.T. | Q38: Ratna Santi, Ashwin Sasongko Sastrosubroto | R38: Jurnal | S38: Published | T38: Interdisciplinary Journal of Information, Knowledge, and Management | U38: Ya | V38: Q3 | W38: PI | X38: https://www.informingscience.org/Publications/5499 | Y38: https://doi.org/10.28945/5499 | AB38: Bibliometrics for Analysing Business Opportunities and Players in the Pharmaceuticals Fields | AC38: Accepted | AD38: https://doi.org/10.1504/IJTLID.2025.10065144
A39: 34 | B39: =IF(OR(E39<>"",F39<>""),IF(B39="",NOW(),B39),"") -> 45803.311 | C39: Mei | E39: Analysis of Factors Influencing Digital Transformation of Tourism Villages: Evidence from Bogor, Indonesia | F39: Rekayasa Pengetahuan dan Data (Knowledge and Data Engineering) | G39: Dr. Foni Agus Setiawan, M.Kom. | Q39: Isbandriyati Muthmainnah, Iis Anisa Yulia, Aditya Sugih Setiawan, Immas Nurhayati, Bambang Hengky Rainanto, Sri Harini, Endri | R39: Jurnal | S39: Published | T39: Tourism and Hospitality (MDPI) | U39: Ya | V39: Q1 | W39: PI | X39: https://www.mdpi.com/2673-5768/6/2/57 | Y39: https://doi.org/10.3390/tourhosp6020057 | AB39: A Lexical and Post-lexical Prosodic Documentation of Embaloh Language | AC39: Published | AD39: https://doi.org/10.33736/ils.6025.2024
A40: 35 | B40: =IF(OR(E40<>"",F40<>""),IF(B40="",NOW(),B40),"") -> 45803.609 | C40: Triwulan II | E40: Analyzing Halal Concerns on Korean Food Using Text-Mining: Perspectives from Indonesian Social Media Users | F40: Temu Kembali Informasi (Information Retrieval) | G40: Ekasari Nugraheni, M.T. | H40: Andria Arisal, M. Eng. | I40: Andri Fachrur Rozie, M. Eng. | J40: Ir. Dianadewi Riswantini, M. Sc., M.B.A. | K40: Dr. Purnomo Husnul Khotimah, M.T | L40: Dr. Wiwin Suwarningsih, M.T. | R40: Jurnal | S40: Published | T40: International Journal on Food System Dynamics | U40: Ya | V40: Q2 | W40: PI | X40: https://brill.com/view/journals/fsd/aop/article-10.1163-18696945-bja00006/article-10.1163-18696945-bja00006.xml | Y40: https://doi.org/10.1163/18696945-bja00006 | AB40: Feature Selection and Performance Evaluation of Buzzer Classification Model | AC40: Published | AD40: https://doi.org/10.25077/josi.v23.n1.p1-14.2024
A41: 36 | B41: =IF(OR(E41<>"",F41<>""),IF(B41="",NOW(),B41),"") -> 45804.841 | C41: Triwulan II | E41: The Development of A Digital Transformation Model for Higher Education Using the Object-Process Methodology | F41: Interaksi Manusia-Komputer dan Visualisasi (Human Computer Interaction and Visualisation) | G41: Rio Nurtantyana, S.Pd., M.Pd., M.Sc., Ph.D. | H41: Aria Bisri, S.Kom. M.T. | I41: Abdurrakhman Prasetyadi, M.P | Q41: Atina Putri, Allya Paramita Koesoema, Yusep Rosmansyah | R41: Prosiding | S41: Published | T41: International Conference on Computer, Control, Informatics and its Applications, IC3INA | U41: Ya | W41: PI | X41: https://www.scopus.com/record/display.uri?eid=2-s2.0-85211933869&origin=recordpage | Y41: https://doi.org/10.1109/IC3INA64086.2024.10732551 | Z41: IC3INA tahun 2024 akhir, belum diklaim | AB41: Rice Phenology Classification Model Based on Sentinel-1 Using Machine 2 Learning Method on Google Earth Engine | AC41: Published | AD41: https://doi.org/10.1080/07038992.2024.2368036
A42: 37 | B42: =IF(OR(E42<>"",F42<>""),IF(B42="",NOW(),B42),"") -> 45804.857 | C42: Mei | E42: Ihoya: knowledge management system based on community using User-Centered Design (UCD) method | F42: Rekayasa Pengetahuan dan Data (Knowledge and Data Engineering) | G42: Siti Kania Kushadiani, S.T., M.Kom. | Q42: Muhammad Rafi, Sulistyo Puspitodjati, Niken Fitria Apriani, Shidiq Al Hakim, Al Hafiz Akbar Maulana Siagian, Slamet Riyanto, Rodiah | R42: Jurnal | S42: Published | T42: International Journal of Information Technology (Singapore) | U42: Ya | V42: Q2 | W42: PI | X42: https://www.scopus.com/record/display.uri?eid=2-s2.0-85211901572&origin=recordpage | Y42: https://doi.org/10.1007/s41870-024-02344-5 | AB42: Performance of Weather Research Forecasting Model for Seasonal Prediction of Precipitation over Indonesian Maritime Continent | AC42: Published | AD42: https://doi.org/10.1016/j.kjs.2024.100293
...

Sheet PWRP
A1: PURWARUPA
A4: DIISI OLEH PJ MONEV | E4: PUSAT RISET SAINS DATA DAN INFORMASI | G4: SIVITAS PRSDI
A5: NO | B5: Periode Input | C5: Periode Stamp | E5: JUDUL | F5: KELOMPOK RISET | G5: 1 | H5: 2 | I5: 3 | J5: 4 | K5: 5 | L5: 6 | M5: 7 | N5: 8 | O5: 9 | P5: 10 | Q5: NON SIVITAS PRSDI | R5: JENIS | S5: STATUS | T5: MEMILIKI MITRA ? | U5: NAMA MITRA | V5: No KI yang termanfaatkan dalam Lisensi | W5: UPLOAD GDRIVE | X5: CATATAN | Y5: Evidence bisa dalam bentuk Dokumentasi, perjanjian lisensi, dokumen sertifikan/terdaftar di DJKI
A6: 1 | B6: =IF(OR(E6<>"",F6<>""),IF(B6="",NOW(),B6),"") -> 45735.472 | E6: Digital Twin untuk Analisis Risiko Banjir Kota Bandung | F6: Interaksi Manusia-Komputer dan Visualisasi (Human Computer Interaction and Visualisation) | G6: Abdurrakhman Prasetyadi, M.P | H6: Prof. Dr. Ana Hadiana, M.Eng.Sc. | I6: Dr. Esa Prakasa, MT | J6: M. Yudhi Rezaldi, Ph.D | K6: Dr. Ambar Yoganingrum | L6: Arafat Febriandirza, Ph.D | M6: Aria Bisri, S.Kom. M.T. | N6: Rio Nurtantyana, S.Pd., M.Pd., M.Sc., Ph.D. | O6: Rumadi, S.T., M.T. | P6: Christine Cecylia Munthe, S.Kom. | Q6: Dr. Ary Setijadi Prihatmanto, Prof. Ridwan Sutriadi (ITB), Ai Sulastri (UPI) | R6: Software Prototype | S6: Skala Uji Lab | T6: Belum | W6: PWRP
A7: 2 | B7: =IF(OR(E7<>"",F7<>""),IF(B7="",NOW(),B7),"") -> 45874.616 | E7: Hak Cipta Program Komputer : Aplikasi Pemilu Elektronik (e-Voting) (000535510) | F7: Pemerintahan Digital (Digital Government) | G7: Dra. Andrari Grahitandaru, M.Sc. | H7: Drs. Zain Saifullah, M.Sc. | I7: Ir. Gunarso | S7: Lisensi | T7: Sudah | U7: PT. Inti Konten Indonesia (INTENS) | W7: PWRP
A8: 3 | B8: =IF(OR(E8<>"",F8<>""),IF(B8="",NOW(),B8),"") -> 45998.454 | C8: Triwulan IV | E8: Sistem Big Data Bahasa dan Sastra Lisan Perbatasan (BAHASAN) | F8: Rekayasa Pengetahuan dan Data (Knowledge and Data Engineering) | G8: Dr. Foni Agus Setiawan, M.Kom. | R8: Software Prototype | S8: Lisensi | T8: Sudah | U8: STKIP Persada Khatulistiwa, Sintang | V8: EC002025055955 | W8: PWRP
A9: 4 | B9: =IF(OR(E9<>"",F9<>""),IF(B9="",NOW(),B9),"") -> 45999.676 | E9: BugisLingua - Sistem Terjemahan Bahasa Bugis | F9: Pengolahan Bahasa Alami (Natural Language Processing) | G9: Dr. Eng. Ir Yuyun, S.Kom., M.T | H9: Agung Santosa, BSEE, M.Kom | I9: Lyla Ruslana Aini | J9: Ir. Andi Djalal Latief, M.S. | K9: Ir. Gunarso | L9: Siska Pebiana S.Kom., M.Kom. | M9: Radhiyatul Fajri, S.Kom, M.Pd.T, M.Kom. | N9: Nuryani | O9: Elvira Nurfadhilah, S.Komp., M. Kom | P9: M. Teduh Uliniansyah, B.Eng., M.Sc., Ph.D. | Q9: Gusnawaty, Hazriani, Pammuda | R9: Software Prototype | S9: Skala Uji Lab | T9: Sudah | U9: Fakultas Ilmu Budaya Univ. Hasanuddin | W9: PWRP | X9: Mohon evidence nomor HKI
A10: 5 | B10: =IF(OR(E10<>"",F10<>""),IF(B10="",NOW(),B10),"") -> 45999.682 | E10: Alat bantu pemeriksaan hasil rekam ujaran Bahasa Bugis | F10: Pengolahan Bahasa Alami (Natural Language Processing) | G10: Agung Santosa, BSEE, M.Kom | H10: Dr. Eng. Ir Yuyun, S.Kom., M.T | I10: Lyla Ruslana Aini | J10: Ir. Andi Djalal Latief, M.S. | K10: Ir. Gunarso | L10: Siska Pebiana S.Kom., M.Kom. | M10: Radhiyatul Fajri, S.Kom, M.Pd.T, M.Kom. | N10: Nuryani | O10: Elvira Nurfadhilah, S.Komp., M. Kom | P10: M. Teduh Uliniansyah, B.Eng., M.Sc., Ph.D. | Q10: Gusnawaty, Hazriani, Pammuda | S10: Skala Uji Lab | T10: Sudah | U10: Fakultas Ilmu Budaya Univ. Hasanuddin | W10: PWRP | X10: Mohon evidence nomor HKI
A11: 6 | B11: =IF(OR(E11<>"",F11<>""),IF(B11="",NOW(),B11),"") -> 46001.642 | C11: Triwulan IV | E11: Hak Cipta INACOVED (Dataset) | F11: Temu Kembali Informasi (Information Retrieval) | G11: Dr. Purnomo Husnul Khotimah, M.T | H11: Andri Fachrur Rozie, M. Eng. | I11: Andria Arisal, M. Eng. | J11: Ekasari Nugraheni, M.T. | K11: Ir. Dianadewi Riswantini, M. Sc., M.B.A. | L11: Dr. Wiwin Suwarningsih, M.T. | S11: Lisensi | T11: Sudah | U11: FMIPA Universitas Lampung | V11: EC002023112261 | W11: PWRP
A12: 7 | B12: =IF(OR(E12<>"",F12<>""),IF(B12="",NOW(),B12),"") -> 46001.642 | C12: Triwulan IV | E12: Hak Cipta Bangkit-TS (Program Komputer) | F12: Temu Kembali Informasi (Information Retrieval) | G12: Dr. Purnomo Husnul Khotimah, M.T | H12: Andri Fachrur Rozie, M. Eng. | I12: Andria Arisal, M. Eng. | Q12: Febi Siti Sutria Ningsih, Dian Kurniasari, Warsono | R12: Software Prototype | S12: Lisensi | T12: Sudah | U12: FMIPA Universitas Lampung | V12: EC002022107186 | W12: PWRP
A13: 8 | B13: =IF(OR(E13<>"",F13<>""),IF(B13="",NOW(),B13),"") | W13: PWRP
A14: 9 | B14: =IF(OR(E14<>"",F14<>""),IF(B14="",NOW(),B14),"") | W14: PWRP
A15: 10 | B15: =IF(OR(E15<>"",F15<>""),IF(B15="",NOW(),B15),"") | W15: PWRP
A16: 11 | B16: =IF(OR(E16<>"",F16<>""),IF(B16="",NOW(),B16),"") | W16: PWRP
A17: 12 | B17: =IF(OR(E17<>"",F17<>""),IF(B17="",NOW(),B17),"") | W17: PWRP
A18: 13 | B18: =IF(OR(E18<>"",F18<>""),IF(B18="",NOW(),B18),"") | W18: PWRP
A19: 14 | B19: =IF(OR(E19<>"",F19<>""),IF(B19="",NOW(),B19),"") | W19: PWRP
A20: 15 | B20: =IF(OR(E20<>"",F20<>""),IF(B20="",NOW(),B20),"") | W20: PWRP
A21: 16 | B21: =IF(OR(E21<>"",F21<>""),IF(B21="",NOW(),B21),"") | W21: PWRP
A22: 17 | B22: =IF(OR(E22<>"",F22<>""),IF(B22="",NOW(),B22),"") | W22: PWRP
A23: 18 | B23: =IF(OR(E23<>"",F23<>""),IF(B23="",NOW(),B23),"") | W23: PWRP
A24: 19 | B24: =IF(OR(E24<>"",F24<>""),IF(B24="",NOW(),B24),"") | W24: PWRP
... A53: 48 | B53: =IF(OR(E53<>"",F53<>""),IF(B53="",NOW(),B53),"") | W53: PWRP

Sheet Dana Eks + PKS
A3: DIISI OLEH PJ MONEV | E3: PUSAT RISET SAINS DATA DAN INFORMASI | G3: PIC/KORD KEGIATAN (SIVITAS PRSDI) | Y3: KERJA SAMA | AA3: PERJANJIAN | AC3: EVIDEN/DAKUNG
A4: NO | B4: Periode Input | C4: Periode Stamp | E4: JUDUL | F4: KELOMPOK RISET | G4: 1 | H4: 2 | I4: 3 | J4: 4 | K4: 5 | L4: 6 | M4: 7 | N4: 8 | O4: 9 | P4: 10 | Q4: NON SIVITAS PRSDI | R4: TIPE | S4: JENIS | T4: SUMBER | U4: OUTPUT | V4: PIHAK K3 | W4: NILAI | X4: KETERANGAN | Y4: NO KERJASAMA | Z4: TANGGAL KERJASAMA | AA4: NO PERJANJIAN | AB4: TANGGAL PERJANJIAN | AC4: LINK UPLOAD | AD4: STATUS UPLOAD | AE4: TAHUN PKS | AF4: NO KI YANG TERMANFAATKAN | AG4: LINK BUKTI DUKUNG | AH4: CATATAN
A5: 1 | B5: =IF(OR(E5<>"",F5<>""),IF(B5="",NOW(),B5),"") -> 45722.426 | C5: Triwulan I | E5: Pengembangan Aplikasi Model Pembelajaran Al-Qur'an Metode Yusro | F5: Interaksi Manusia-Komputer dan Visualisasi (Human Computer Interaction and Visualisation) | G5: Ridwan Suhud, S.Kom., M.T. | H5: Dr. Esa Prakasa, MT | I5: Prof. Dr. Ana Hadiana, M.Eng.Sc. | J5: Abdurrakhman Prasetyadi, M.P | K5: M. Yudhi Rezaldi, Ph.D | L5: Aria Bisri, S.Kom. M.T. | M5: Andria Arisal, M. Eng. | N5: Andri Fachrur Rozie, M. Eng. | Q5: Dr. Bambang Setiadi | R5: Kerjasama | S5: Dalam Negeri | V5: Universitas Swadaya Gunung Jati | Y5: No. 002/V/KS/01/2025 dan 01/Lemlit-UGJ/I/2025 | Z5: 45667 | AC5: Dana Eksternal & Kerjasama | AD5: Sudah | AE5: 2022 addendum 2024 | AH5: mahasiswa PKL 6 orang dan MBKM 6 orang
A6: 2 | B6: =IF(OR(E6<>"",F6<>""),IF(B6="",NOW(),B6),"") -> 45722.426 | C6: Triwulan II | E6: Pengembangan Platform Digital Smart Research Environment (SRE) yang bertumpu pada Konektivitas Kecerdasan Buatan dan Kolaborasi Pakar untuk Mendukung Perkembangan Riset dan Inovasi di Indonesia | F6: Interaksi Manusia-Komputer dan Visualisasi (Human Computer Interaction and Visualisation) | G6: Rio Nurtantyana | H6: Dr. Ambar Yoganingrum | I6: Arafat Febriandirza, Ph.D | J6: M. Yudhi Rezaldi, Ph.D | K6: Abdurrakhman Prasetyadi, M.P | L6: Aria Bisri, S.Kom. M.T. | M6: Rumadi, S.T., M.T. | R6: Dana Eksternal | S6: Dalam Negeri | T6: RIIM | U6: In Cash | W6: 164200000 | X6: RIIM Kompetitif Gel. 7 | Y6: NOMOR 61/II.7/HK/2024 | Z6: 45650 | AC6: Dana Eksternal & Kerjasama | AD6: Sudah | AE6: 2025
A7: 3 | B7: =IF(OR(E7<>"",F7<>""),IF(B7="",NOW(),B7),"") -> 45733.363 | C7: Mei | E7: Metaspeak: Platform Pembelajaran Multi-Bahasa Mandiri Berbasis Metaverse Untuk Mengatasi Kecemasan Berbahasa | F7: Interaksi Manusia-Komputer dan Visualisasi (Human Computer Interaction and Visualisation) | G7: M. Yudhi Rezaldi, Ph.D | H7: Dr. Esa Prakasa, MT | I7: Dr. Purnomo Husnul Khotimah, M.T | R7: Kerjasama | S7: Dalam Negeri | V7: LPPM Tel U | X7: PKS tahun 2024, Jangka waktu 3 tahun | Y7: 160/V/KS/06/2024 | Z7: 45470 | AC7: Dana Eksternal & Kerjasama | AD7: Sudah | AE7: 2024 | AH7: - Paper published di Q2 Scopus - Perlu konfirmasi apa dpt dana external di tahun 2025
A8: 4 | B8: =IF(OR(E8<>"",F8<>""),IF(B8="",NOW(),B8),"") -> 45736.463 | C8: Triwulan I | E8: Pengembangan Sistem Identifikasi Fitoplankton Perairan Indonesia Dengan Menggunakan Computer Vision | F8: Interaksi Manusia-Komputer dan Visualisasi (Human Computer Interaction and Visualisation) | G8: Dr. Esa Prakasa, MT | H8: Aria Bisri, S.Kom. M.T. | Q8: Riyo Wardoyo (PRKAKS), Arief Rachman (ORKM), Diah Radini Noerjito (ORHL), Ovide DWA (UNS), Tri Retnaningsih (UNDIP), Kusworo (UNDIP) | R8: Dana Eksternal | S8: Dalam Negeri | T8: RIIM | U8: In Cash | W8: 90000000 | X8: RIIM Gel. 3, Tahun ke-2 | AA8: B-838/II.7.5/FR.06/5/2023 | AB8: 8 Mei 2023 | AC8: Dana Eksternal & Kerjasama | AD8: Sudah | AE8: 2024 | AH8: Menunggu Pencairan Dana
A9: 5 | B9: 45761 | C9: April | E9: Pengembangan Sistem Kustomisasi Model Bahasa untuk Meningkatkan Akurasi Whisper dalam Pengenalan Ucapan Otomatis Ujung-ke-Ujung | F9: Pengolahan Bahasa Alami (Natural Language Processing) | G9: Dr. Dipl.(FH) Ing Asril, M.Sc | H9: Agung Santosa, BSEE, M.Kom | I9: Lyla Ruslana Aini | J9: Ir. Gunarso | K9: M. Teduh Uliniansyah, B.Eng., M.Sc., Ph.D. | L9: Elvira Nurfadhilah, S.Komp., M. Kom | M9: Siska Pebiana S.Kom., M.Kom. | Q9: Tim PT Bahasa Kita: Oskar Riandi; Izzul Haq Al Hakam;Achmad Satria Putera | R9: Dana Eksternal | S9: Dalam Negeri | T9: RIIM | U9: In Cash | W9: 165600000 | X9: RIIM Kompetitif Gel. 7 | AA9: B-5647/II.7.5/RT.01.01/4/2025 B-6888/III.6/TK.01.03/4/2025 | AB9: 45761 | AC9: Dana Eksternal & Kerjasama | AD9: Sudah | AE9: 2025 | AH9: SK DEPUTI BIDANG FASILITASI RISET DAN INOVASI, BADAN RISET DAN INOVASI NASIONAL, NOMOR 61/II.7/HK/2024 TENTANG PENERIMA PROGRAM RISET DAN INOVASI UNTUK INDONESIA MAJU KOMPETISI GELOMBANG 7
A10: 6 | B10: =IF(OR(E10<>"",F10<>""),IF(B10="",NOW(),B10),"") -> 45805.383 | E10: Pengembangan Platform Digital Smart Research Environment (SRE) yang bertumpu pada Konektivitas Kecerdasan Buatan dan Kolaborasi Pakar untuk Mendukung Perkembangan Riset dan Inovasi di Indonesia | F10: Interaksi Manusia-Komputer dan Visualisasi (Human Computer Interaction and Visualisation) | G10: Rio Nurtantyana | H10: Dr. Ambar Yoganingrum | I10: Arafat Febriandirza, Ph.D | J10: M. Yudhi Rezaldi, Ph.D | K10: Abdurrakhman Prasetyadi, M.P | L10: Aria Bisri, S.Kom. M.T. | M10: Rumadi, S.T., M.T. | R10: Dana Eksternal | S10: Dalam Negeri | T10: RIIM | U10: In Kind | AA10: 384/V/KS/10/2024 | AB10: 45567 | AC10: Dana Eksternal & Kerjasama | AD10: Sudah | AE10: 2024
A11: 7 | B11: =IF(OR(E11<>"",F11<>""),IF(B11="",NOW(),B11),"") -> 45805.402 | C11: Mei | E11: Pengembangan Teknologi Imersif dan Penyediaan Asset Aplikasi 3D | F11: Interaksi Manusia-Komputer dan Visualisasi (Human Computer Interaction and Visualisation) | G11: Abdurrakhman Prasetyadi, M.P | H11: Dr. Esa Prakasa, MT | I11: M. Yudhi Rezaldi, Ph.D | J11: Dr. Ambar Yoganingrum | K11: Arafat Febriandirza, Ph.D | L11: Rio Nurtantyana, S.Pd., M.Pd., M.Sc., Ph.D. | M11: Ridwan Suhud, S.Kom., M.T. | N11: Aria Bisri, S.Kom. M.T. | Q11: Cahyo Trianggoro | R11: Kerjasama | S11: Dalam Negeri | U11: In Kind | V11: UPI Cibiru Bandung | Y11: 177/V/KS/06/2024 | Z11: 45456 | AC11: Dana Eksternal & Kerjasama | AD11: Sudah | AE11: 2024 | AH11: Kerjasama masih berlangsung, untuk Dana Eksternal (Rp. 36.900.000) sudah dikalim 2024
A12: 8 | B12: 45805 | C12: Triwulan IV | E12: PERANCANGAN ASSET VISUAL GAME (2D/3D) UNTUK MEMPERKENALKAN KEBUDAYAAN DAERAH YANG ADA DI SULAWESI DAN KEPULAUAN NUSA TENGGARA | F12: Interaksi Manusia-Komputer dan Visualisasi (Human Computer Interaction and Visualisation) | G12: M. Yudhi Rezaldi, Ph.D | H12: Ridwan Suhud, S.Kom., M.T. | I12: Abdurrakhman Prasetyadi, M.P | J12: Aang Gunawan S, S.Kom., M.T. | K12: Rio Nurtantyana, S.Pd., M.Pd., M.Sc., Ph.D. | L12: Dr. Ambar Yoganingrum | M12: Aria Bisri, S.Kom. M.T. | N12: Arafat Febriandirza, Ph.D | O12: Dr. Esa Prakasa, MT | P12: Prof. Dr. Ana Hadiana, M.Eng.Sc. | Q12: Cahyo Trianggoro, Niken Fitria Apriani, Dian Andriana | R12: Kerjasama | S12: Dalam Negeri | U12: In Kind | V12: Universitas Telkom | Y12: 232/V/KS/07/2024 | Z12: 45490 | AC12: Dana Eksternal & Kerjasama | AE12: 2024 | AH12: Jangka waktu 2 tahun menghasilkan HKI : EC002025132928, 16 September 2025
A13: 9 | B13: 45805 | C13: Triwulan IV | E13: PERANCANGAN ASSET VISUAL GAME (2D/3D) UNTUK MEMPERKENALKAN KEBUDAYAAN DAERAH MALUKU DAN PAPUA | F13: Interaksi Manusia-Komputer dan Visualisasi (Human Computer Interaction and Visualisation) | G13: M. Yudhi Rezaldi, Ph.D | H13: Ridwan Suhud, S.Kom., M.T. | I13: Abdurrakhman Prasetyadi, M.P | J13: Aang Gunawan S, S.Kom., M.T. | K13: Rio Nurtantyana, S.Pd., M.Pd., M.Sc., Ph.D. | L13: Dr. Ambar Yoganingrum | M13: Aria Bisri, S.Kom. M.T. | N13: Arafat Febriandirza, Ph.D | O13: Dr. Esa Prakasa, MT | P13: Prof. Dr. Ana Hadiana, M.Eng.Sc. | Q13: Cahyo Trianggoro, Niken Fitria Apriani | R13: Kerjasama | S13: Dalam Negeri | U13: In Kind | V13: Universitas Pasundan | Y13: 176/V/KS/06/2024 | Z13: 45462 | AC13: Dana Eksternal & Kerjasama | AE13: 2024 | AH13: Jangka waktu 2 tahun
A14: 10 | B14: =IF(OR(E14<>"",F14<>""),IF(B14="",NOW(),B14),"") -> 45825.595 | E14: Penerapan Algoritma Komodo Mlipir dalam Menyelesaikan Vehicle Routing Problem untuk Rute Wisata Multi-Hari di Yogyakarta | F14: Interaksi Manusia-Komputer dan Visualisasi (Human Computer Interaction and Visualisation) | G14: Rio Nurtantyana, S.Pd., M.Pd., M.Sc., Ph.D. | Q14: Abdurahman Baizal | R14: Dana Eksternal | S14: Dalam Negeri | T14: RIIM | U14: In Kind | V14: Telkom University | W14: 104000000 | X14: RIIM Gel 7, Tahun ke-1 | AC14: Dana Eksternal & Kerjasama | AE14: 2024 | AH14: Jangka Waktu 3 tahun Dana external sudah d klaim 2024
A15: 11 | B15: =IF(OR(E15<>"",F15<>""),IF(B15="",NOW(),B15),"") -> 45862.832 | C15: Juli | E15: Kolaborasi Riset Di Bidang Kesehatan Jantung | F15: Interaksi Manusia-Komputer dan Visualisasi (Human Computer Interaction and Visualisation) | G15: Dr. Esa Prakasa, MT | H15: Dr. Purnomo Husnul Khotimah, M.T | R15: Kerjasama | S15: Dalam Negeri | T15: Mitra/Universitas | V15: Telkom University | Y15: 18/V/KS/04/2022 dan 090/SAM4/RC-HUMIC/2022 | Z15: 21 April 2022 | AC15: Dana Eksternal & Kerjasama | AD15: Sudah
A16: 12 | B16: =IF(OR(E16<>"",F16<>""),IF(B16="",NOW(),B16),"") -> 45862.842 | C16: Juli | E16: Kolaborasi Riset Pengembangan Sistem Penerjemah Bahasa Isyarat BISINDO Menggunakan Analisis Video | F16: Interaksi Manusia-Komputer dan Visualisasi (Human Computer Interaction and Visualisation) | G16: Dr. Esa Prakasa, MT | R16: Kerjasama | S16: Dalam Negeri | T16: Mitra/Universitas | V16: PT. Inovasi Disabilitas Indonesia | Y16: 54/V/KS/07/2022 dan 20.04/Hear Me-PKS/VII/2022 | Z16: 14 Juli 2022 | AC16: Dana Eksternal & Kerjasama | AD16: Sudah | AE16: 2021 | AH16: paper accepted 1 jurnal int.
A17: 13 | B17: =IF(OR(E17<>"",F17<>""),IF(B17="",NOW(),B17),"") -> 45862.855 | C17: Juli | E17: Penelitian dan Pengembangan Human-Centered Computing Untuk Digital Library dan Distance Learning | F17: Interaksi Manusia-Komputer dan Visualisasi (Human Computer Interaction and Visualisation) | G17: Dr. Esa Prakasa, MT | H17: Andre Sihombing, S.Kom., M.Sc. | R17: Kerjasama | S17: Dalam Negeri | T17: Mitra/Universitas | V17: UI | Y17: 531/V/KS/11/2023 dan PKS-99/UN2.F11.D/HKP.05.01/2023 | Z17: 3 November 2023 | AC17: Dana Eksternal & Kerjasama | AD17: Sudah | AE17: 2024 | AH17: mahasiswa MBKM 1
A18: 14 | B18: =IF(OR(E18<>"",F18<>""),IF(B18="",NOW(),B18),"") -> 45880.358 | C18: Agustus | E18: Collaboration and Co-Development of Human-Computer Interaction and Visualization Through Smart Robotics and Mobile Applications for Authentic Contextual Exploration | F18: Interaksi Manusia-Komputer dan Visualisasi (Human Computer Interaction and Visualisation) | G18: Arafat Febriandirza, Ph.D | R18: Kerjasama | S18: Luar Negeri | T18: Mitra/Universitas | V18: Taiwan Vest Information INC | X18: Taiwan | Y18: Perjanjian Kerjasama | Z18: 8 Agustus 2025 | AC18: Dana Eksternal & Kerjasama | AD18: Sudah | AG18: https://drive.google.com/drive/folders/1pfWg0y9PDMakt1iYy0pe81S0Me33MgWo?usp=drive_link | AH18: SURAT TUGAS NOMOR B-303/III.6.3/RT.07.00/1/2025, Tgl. 7 Januari 2025
A19: 15 | B19: =IF(OR(E19<>"",F19<>""),IF(B19="",NOW(),B19),"") -> 45880.366 | E19: Kerjasama Internasional, Ttd LoI PRSDI dengan UKM Malaysia, KelRis HCIV | F19: Interaksi Manusia-Komputer dan Visualisasi (Human Computer Interaction and Visualisation) | G19: Arafat Febriandirza, Ph.D | R19: Kerjasama | S19: Luar Negeri | T19: Mitra/Universitas | V19: UKM Malaysia | AC19: Dana Eksternal & Kerjasama | AH19: Tahun ke-2, Masih Dalam Proses Monitoring dan Evaluasi
A20: 16 | B20: =IF(OR(E20<>"",F20<>""),IF(B20="",NOW(),B20),"") -> 45881.341 | E20: PRSDI - ITENAS | F20: Interaksi Manusia-Komputer dan Visualisasi (Human Computer Interaction and Visualisation) | G20: Arafat Febriandirza, Ph.D | R20: Kerjasama | S20: Dalam Negeri | T20: Mitra/Universitas | V20: ITENAS | AC20: Dana Eksternal & Kerjasama
A21: 17 | B21: =IF(OR(E21<>"",F21<>""),IF(B21="",NOW(),B21),"") -> 45893.781 | C21: Agustus | E21: Kegiatan Penelitian dan Pengembangan Platform Kolaborasi Digital Dengan Teknologi Visualisasi Berbasis Knowledge Graph | F21: Interaksi Manusia-Komputer dan Visualisasi (Human Computer Interaction and Visualisation) | G21: Rio Nurtantyana, S.Pd., M.Pd., M.Sc., Ph.D. | R21: Kerjasama | S21: Dalam Negeri | T21: Mitra/Universitas | V21: Unversitas Brawijaya | Y21: 384/V/KS/10/2024 dan 03404/UN10.F1501/B/KS/2024 | Z21: 02/10/2024 | AC21: Dana Eksternal & Kerjasama | AD21: Sudah
A22: 18 | B22: =IF(OR(E22<>"",F22<>""),IF(B22="",NOW(),B22),"") -> 45894.437 | C22: Agustus | E22: Kolaborasi Dalam Riset dan Inovasi Dalam Arah Strategis Dan Tematik, Serta Mekanisme Dalam Metaverse, Realitas Virtual, Realitas Tertambah, Hologram, Realitas Terpanjang, Realitas Campuran, Dan Bidang-Bidang Terkait | F22: Interaksi Manusia-Komputer dan Visualisasi (Human Computer Interaction and Visualisation) | G22: M. Yudhi Rezaldi, Ph.D | R22: Kerjasama | S22: Luar Negeri | T22: Mitra/Universitas | V22: IVI - Universiti Kebangsaan Malaysia (UKM) | X22: UKM Malaysia | Y22: Surat Pernyataan Kehendak (SPK) | Z22: 7 Agustus 2025 | AC22: Dana Eksternal & Kerjasama | AD22: Sudah
A23: 19 | B23: =IF(OR(E23<>"",F23<>""),IF(B23="",NOW(),B23),"") -> 45924.823 | C23: Triwulan III | E23: Riset Dibidang Teknologi Data-Driven Analytic Untuk Mendukung Pencapaian Sustainable Development Goals | F23: Interaksi Manusia-Komputer dan Visualisasi (Human Computer Interaction and Visualisation) | G23: Aria Bisri, S.Kom. M.T. | R23: Kerjasama | S23: Dalam Negeri | T23: Mitra/Universitas | U23: In Kind | V23: Institut Teknologi Sumatera | Y23: 344/V/KS/09/2025 dan 249/IT9.3.1/HK.08.00/2025 | Z23: 15/09/2025 | AC23: Dana Eksternal & Kerjasama | AD23: Sudah
A24: 20 | B24: =IF(OR(E24<>"",F24<>""),IF(B24="",NOW(),B24),"") -> 45938.434 | C24: Oktober | E24: BRICS New Industry “Golden Egret” Excellence Scholarship 2025 BPIC Training Program on Industrial Green Development and Digitalization | F24: Interaksi Manusia-Komputer dan Visualisasi (Human Computer Interaction and Visualisation) | G24: Arafat Febriandirza, Ph.D | R24: Dana Eksternal | S24: Luar Negeri | T24: Mitra/Universitas | U24: In Kind | W24: 70806550 | AC24: Dana Eksternal & Kerjasama | AD24: Sudah
A25: 21 | B25: =IF(OR(E25<>"",F25<>""),IF(B25="",NOW(),B25),"") -> 45722.426 | C25: Triwulan I | E25: Penerapan Big Data Cognitive Analytics Terhadap Pariwisata dan Ekonomi Kreatif | F25: Pemerintahan Digital (Digital Government) | G25: Rezzy Eko Caraka ,S.Si.,M.Sc(RES).,PhD. | H25: Dra. Andrari Grahitandaru, M.Sc. | I25: Drs. Zain Saifullah, M.Sc. | J25: Nimas Ayu Untariyati, S.Kom, M.T.I | K25: Dr. Eng. Budi Nugroho | R25: Kerjasama | S25: Dalam Negeri | V25: Sekolah Tinggi Ilmu Ekonomi Sabang (STIES) Banda Aceh | W25: 187240000 | X25: PKS TAHUN 2024, Jangka waktu 3 tahun | Y25: No. 524/V/KS/12/2024 dan 102/MoU/STIES/VII/2024 | Z25: 45649 | AC25: Dana Eksternal & Kerjasama | AD25: Sudah | AH25: Klaim untuk tahun 2025. Terdapat output KTI. Publikasi di Prosiding / International Conference (Sheet PI No 38) = Sudah di input (no.5), dan sudah di klaim
A26: 22 | B26: =IF(OR(E26<>"",F26<>""),IF(B26="",NOW(),B26),"") -> 45861.352 | C26: Juli | E26: Sinergi Dibidang Penelitian, Pengembangan, Pengkajian, Penerapan Ilmu Pengetahuan dan Teknologi Serta Investasi dan Inovasi Untuk Mendukung Pembangunan di Kabupaten Muara Enim | F26: Pemerintahan Digital (Digital Government) | G26: Dra. Andrari Grahitandaru, M.Sc. | R26: Kerjasama | S26: Dalam Negeri | V26: Pemkab Muara Enim | Y26: 119/21/IV/2025 dan `51/I/KS/07/2025 | Z26: 17 Juli 2025 | AC26: Dana Eksternal & Kerjasama | AD26: Sudah | AE26: 2024 | AH26: PKS tahun 2024 Jangka waktu 3 Tahun
A27: 23 | B27: =IF(OR(E27<>"",F27<>""),IF(B27="",NOW(),B27),"") -> 45862.884 | C27: Triwulan IV | E27: Hak Cipta Program Komputer : Aplikasi Pemilu Elektronik (e-Voting) (000535510) | F27: Pemerintahan Digital (Digital Government) | G27: Dra. Andrari Grahitandaru, M.Sc. | H27: Drs. Zain Saifullah, M.Sc. | I27: Ir. Gunarso | R27: Kerjasama | S27: Dalam Negeri | T27: Mitra/Universitas | V27: PT. Inti Konten Indonesia (INTENS) | X27: Perjanjian Lisensi | AA27: B-972/II.8/MR.01.01/3/2024 dan 007/PKS/INTENS/III/2024 | AB27: 45370 | AC27: Dana Eksternal & Kerjasama | AD27: Sudah | AE27: 2024 | AG27: https://drive.google.com/drive/u/1/search?q=PKS | AH27: Jangka Waktu 5 tahun Tahun 2025 PT Intens ( Perjanjian Lisensi) untuk penerapan eVoting di Kab Indramayu, Kab Krawang dan Kab Gresik. Apakah menghasilkan lisensi di tahun 2025 ?
A28: 24 | B28: =IF(OR(E28<>"",F28<>""),IF(B28="",NOW(),B28),"") -> 45862.898 | C28: Juli | E28: Penelitian, Pengembangan, Pengkajian, dan Penerapan, Serta Invensi dan Inovasi di Kabupaten Belitung | F28: Pemerintahan Digital (Digital Government) | G28: Dra. Andrari Grahitandaru, M.Sc. | H28: Dr. Esa Prakasa, MT | R28: Kerjasama | S28: Dalam Negeri | T28: Mitra/Universitas | V28: Kab. Belitung | Y28: 87/I/KS/10/2024 dan 181/06/NK/I/2024 | Z28: 01-10-2024 | AC28: Dana Eksternal & Kerjasama | AD28: Sudah | AE28: 2024 | AG28: https://drive.google.com/drive/u/1/search?q=pks
A29: 25 | B29: =IF(OR(E29<>"",F29<>""),IF(B29="",NOW(),B29),"") -> 45733.363 | C29: Mei | E29: Riset dan Pengembangan Mesin Penerjemah Bahasa Makassar dan Bahasa Cia-cia ke Bahasa Indonesia | F29: Pengolahan Bahasa Alami (Natural Language Processing) | G29: M. Teduh Uliniansyah, B.Eng., M.Sc., Ph.D. | R29: Kerjasama | S29: Dalam Negeri | V29: Universitas Handayani Makassar | X29: PKS tahun 2024, Jangka waktu 3 tahun | AA29: 444/V/KS/10/2024 | AB29: 04/11/2024 | AC29: Dana Eksternal & Kerjasama | AD29: Sudah
A30: 26 | B30: =IF(OR(E30<>"",F30<>""),IF(B30="",NOW(),B30),"") -> 45733.363 | E30: Chatbot Lisa | F30: Pengolahan Bahasa Alami (Natural Language Processing) | G30: Elvira Nurfadhilah, S.Komp., M. Kom | R30: Kerjasama | S30: Dalam Negeri | V30: Unit Hemodialisis RSUD Cimacan Cianjur | AA30: 335/V/KS/09/2024 | AB30: 01/10/2024 | AC30: Dana Eksternal & Kerjasama | AH30: Mohon PKS di Upload atau mohon buat surat keterangan pemanfaatan pada tahun 2025 dari RSUD | AI30: Rencana KI Termanfaatkan
A31: 27 | B31: =IF(OR(E31<>"",F31<>""),IF(B31="",NOW(),B31),"") -> 45735.47 | C31: Juli | E31: Riset dan Pengembangan Part of Speech (POS) Tag dan Mesin Penerjemah Bahasa Bugis ke Bahasa Indonesia | F31: Pengolahan Bahasa Alami (Natural Language Processing) | G31: Dr. Eng. Ir Yuyun, S.Kom., M.T | R31: Kerjasama | S31: Dalam Negeri | T31: Mitra/Universitas | V31: Univ. Hasanuddin | W31: 512160000 | Y31: 335/V/KS/09/2024 dan 3782/UN4.9.7/HK.07.00/2024 | Z31: 02-09-2024 | AC31: Dana Eksternal & Kerjasama | AD31: Sudah | AE31: 2023, Amandemen 2025 berakhir 2030
A32: 28 | B32: =IF(OR(E32<>"",F32<>""),IF(B32="",NOW(),B32),"") -> 45736.487 | C32: Triwulan I | E32: ASEAN-Korea Cooperation Fund (AKCF) - Korea Institute of Science and Technology Information (KISTI) | F32: Pengolahan Bahasa Alami (Natural Language Processing) | G32: Iftitahu Ni'mah, S.Kom., M.I.T. | Q32: Dr. Rifki Sadikin (PR Komputasi) | R32: Dana Eksternal | S32: Luar Negeri | T32: Mitra/Universitas | U32: In Kind | V32: Korea Institute of Science and Technology Information (KISTI) | W32: 26169600 | AC32: Dana Eksternal & Kerjasama | AD32: Sudah | AE32: 2022 | AH32: Jangka Waktu 5 tahun
A33: 29 | B33: =IF(OR(E33<>"",F33<>""),IF(B33="",NOW(),B33),"") -> 45787.816 | C33: Juli | E33: Course on Digital Governance, Cybersecurity and A.I. Adoption for Public Service. | F33: Pengolahan Bahasa Alami (Natural Language Processing) | G33: Siska Pebiana S.Kom., M.Kom. | R33: Dana Eksternal | S33: Luar Negeri | T33: Mitra/Universitas | U33: In Kind | V33: Technical Cooperation Directorate Ministry of Foreign Affairs, Singapore Cooperation Programme | W33: 57757712 | X33: SURAT TUGAS NOMOR B-9626/III.6/TK.02.01/5/2025 | AC33: Dana Eksternal & Kerjasama | AD33: Sudah
A34: 30 | B34: =IF(OR(E34<>"",F34<>""),IF(B34="",NOW(),B34),"") -> 0 | C34: Juli | E34: Visiting Researcher ke Pukyong National University dengan tema "Exploring Food Computing" | F34: Pengolahan Bahasa Alami (Natural Language Processing) | G34: Dr. Kokoy Siti Komariah S.Kom., M.T., M.Eng. | R34: Dana Eksternal | S34: Luar Negeri | T34: Visiting Research | U34: In Kind | V34: Pukyong National University | W34: 40000000 | X34: SURAT TUGAS NOMOR B-4143/III.6/TK.02.01/2/2025 | AC34: Dana Eksternal & Kerjasama | AD34: Sudah | AE34: 2023 | AH34: Jangka Waktu 3 tahun
A35: 31 | B35: =IF(OR(E35<>"",F35<>""),IF(B35="",NOW(),B35),"") -> 45862.904 | C35: Juli | E35: Pendekatan Inovatif Data Analitik Guna Meningkatkan Kualitas Pendidikan dan Pengalaman Belajar Peserta Didik Pada Platform Pembelajaran Daring | F35: Pengolahan Bahasa Alami (Natural Language Processing) | G35: Dr. Kokoy Siti Komariah S.Kom., M.T., M.Eng. | H35: Dr. Esa Prakasa, MT | I35: Rio Nurtantyana, S.Pd., M.Pd., M.Sc., Ph.D. | J35: Satrio Adi Priyambada, S.Kom., M.Kom., Ph.D. | R35: Kerjasama | S35: Dalam Negeri | T35: Mitra/Universitas | V35: Universitas Terbuka | Y35: 258/V/KS/07/2024 dan B/2675/UN31.FST/HK.08.00/2024 | Z35: 01-08-2024 | AC35: Dana Eksternal & Kerjasama | AD35: Sudah | AE35: 2024
A36: 32 | B36: =IF(OR(E36<>"",F36<>""),IF(B36="",NOW(),B36),"") -> 45924.816 | C36: Triwulan III | E36: Development of Smart Grid Ontology for Interoperability and Knowledge Sharing | F36: Pengolahan Bahasa Alami (Natural Language Processing) | G36: M. Teduh Uliniansyah, B.Eng., M.Sc., Ph.D. | R36: Kerjasama | S36: Luar Negeri | T36: Mitra/Universitas | U36: In Kind | V36: California polytechnic state University (Calpoly) USA | Z36: 2025 | AC36: Dana Eksternal & Kerjasama | AD36: Sudah | AE36: 2025 | AH36: Jangka Waktu 1 tahun
